Workbook

Sheet Answer Report 2
A1: Microsoft Excel 16.0 Answer Report
A2: Worksheet: [Case_Intel_Asia_Campaign_FINAL.xlsx]Model 2.
A3: Report Created: 2/11/2020 11:56:25 AM
A4: Result: Solver found a solution. All Constraints and optimality conditions are satisfied.
A5: Solver Engine
B6: Engine: GRG Nonlinear
B7: Solution Time: 0.344 Seconds.
B8: Iterations: 1 Subproblems: 0
A9: Solver Options
B10: Max Time Unlimited, Iterations Unlimited, Precision 0.000001
B11: Convergence 0.0001, Population Size 100, Random Seed 0, Derivatives Central
B12: Max Subproblems Unlimited, Max Integer Sols Unlimited, Integer Tolerance 1%, Assume NonNegative
A14: Objective Cell (Max)
B15: Cell | C15: Name | D15: Original Value | E15: Final Value
B16: $B$50 | C16: Max Clicks Indonesia | D16: 150656.68 | E16: 150656.68
A19: Variable Cells
B20: Cell | C20: Name | D20: Original Value | E20: Final Value | F20: Integer
B21: $D$62 | C21: Marketplace Model | D21: 12080000 | E21: 12080000 | F21: Contin
B22: $D$63 | C22: Premium Model | D22: 1750000 | E22: 1750000 | F22: Contin
B23: $D$64 | C23: Mobile Ads Model | D23: 1500000 | E23: 1500000 | F23: Contin
B24: $D$66 | C24: Marketplace Model | D24: 3000000 | E24: 3000000 | F24: Contin
B25: $D$67 | C25: Premium Model | D25: 1850000 | E25: 1850000 | F25: Contin
B26: $D$68 | C26: Mobile Ads Model | D26: 5150000 | E26: 5150000 | F26: Contin
B27: $D$70 | C27: Marketplace Model | D27: 3000000 | E27: 3000000 | F27: Contin
B28: $D$71 | C28: Premium Model | D28: 1850000 | E28: 1850000 | F28: Contin
B29: $D$72 | C29: Mobile Ads Model | D29: 1500000 | E29: 1500000 | F29: Contin
B30: $D$75 | C30: Premium Model | D30: 5050000 | E30: 5050000 | F30: Contin
B31: $D$76 | C31: Mobile Ads Model | D31: 1500000 | E31: 1500000 | F31: Contin
B32: $D$74 | C32: Marketplace Model | D32: 500000 | E32: 500000 | F32: Contin
... B38: $D$84 | C38: Mobile Ads Model | D38: 1290000 | E38: 1290000 | F38: Contin
A41: Constraints
B42: Cell | C42: Name | D42: Cell Value | E42: Formula | F42: Status | G42: Slack
B43: $L$86 | C43: TOTAL Model | D43: 95000 | E43: $L$86<=$AQ$61 | F43: Binding | G43: 0
B44: $D$81 | C44: Singapore Model | D44: 2730500 | E44: $D$81<=$AJ$81 | F44: Not Binding | G44: 6794500
B45: $D$77 | C45: Philippines Model | D45: 9656795.7 | E45: $D$77<=$AJ$77 | F45: Not Binding | G45: 9393204.3
B46: $D$73 | C46: Pakistan Model | D46: 7050000 | E46: $D$73<=$AJ$73 | F46: Binding | G46: 0
B47: $D$69 | C47: Malaysia Model | D47: 6350000 | E47: $D$69<=$AJ$69 | F47: Not Binding | G47: 12700000
B48: $D$65 | C48: Korea Model | D48: 10000000 | E48: $D$65<=$AJ$65 | F48: Not Binding | G48: 4550000
B49: $D$61 | C49: Indonesia Model | D49: 15330000 | E49: $D$61<=$AJ$61 | F49: Not Binding | G49: 3420000
B50: $AD$101 | C50: Social CTR | D50: 0.3 | E50: $AD$101>=$AG$101 | F50: Binding | G50: 0
...

Sheet Model 2.
A2: Problem | B2: Exceeding budget, optimization of resources
A3: Objective | B3: Decided which marketing plan is better. 1) Agency plan 2) Peter Dingle plans 3) New Plan (other)
A5: EXHIBIT 1: DEMOGRAPHIC AND TECHNOLOGY PENETRATION DATA
A6: Intel AP Markets | B6: Indonesia | C6: Korea | D6: Malaysia | E6: Pakistan | F6: Philippines | G6: Singapore
A7: Population (Ms) 1 | B7: 251.2 | C7: 49 | D7: 29.6 | E7: 193.2 | F7: 105.7 | G7: 5.5
A8: # Internet Users (Ms) 1 | B8: 20 | C8: 39.4 | D8: 15.4 | E8: 20.4 | F8: 8.3 | G8: 3.2
A9: Mobile Phones (Ms) 1 | B9: 248.8 | C9: 52.5 | D9: 36.7 | E9: 111 | F9: 94.2 | G9: 7.8
A10: # Facebook Users (Ms) 2 | B10: 51.1 | C10: 10 | D10: 13.6 | E10: 8 | F10: 29.9 | G10: 2.9
A11: Sources: 1 CIA World Factbook, accessed July 25, 2013; | E11: 2 www.internetworldstats.com/, accessed July 25, 2013.
A13: EXHIBIT 2: INTEL ASIA-PACIFIC FACEBOOK COMMUNITIES (AUGUST 2012)
A14: Intel Market | B14: Indonesia | C14: Korea | D14: Malaysia | E14: Pakistan | F14: Philippines | G14: Singapore
A15: Fans | B15: 778144 | C15: 137801 | D15: 128410 | E15: 316425 | F15: 203907 | G15: 15595
A16: Growth | B16: 8009 | C16: 9361 | D16: 2932 | E16: 18994 | F16: 2204 | G16: 1496
A17: Top Demographic | B17: M 18-24 | C17: F 18-24 | D17: M 18-24 | E17: M 18-24 | F17: M 18-24 | G17: M 18-24
A18: Growth % | B18: =B16/B15 -> 0.010292439 | C18: =C16/C15 -> 0.067931292 | D18: =D16/D15 -> 0.022833113 | E18: =E16/E15 -> 0.060026863 | F18: =F16/F15 -> 0.010808849 | G18: =G16/G15 -> 0.095928182
A19: Source: Intel Asia-Pacific Marketing
A21: Page 9 | H21: 9B13E023
A22: EXHIBIT 4: PRELIMINARY MEDIA PLAN PROPOSED BY IMPACT MARKETING LTD
B23: Indonesia | C23: Korea | D23: Malaysia | E23: Pakistan | F23: Philippines | G23: Singapore | H23: Total
A24: Marketplace
A25: Impressions | B25: 6000000 | C25: 6000000 | D25: 6000000 | E25: 1000000 | F25: 6000000 | G25: 2000000 | H25: 27000000
A26: CPM | B26: 0.53 | C26: 0.88 | D26: 0.6 | E26: 0.57 | F26: 0.56 | G26: 0.71 | H26: 0.64
A27: Cost | B27: 3180 | C27: 5280 | D27: 3600 | E27: 570 | F27: 3360 | G27: 1420 | H27: 17410
A28: Premium
A29: Impressions | B29: 3500000 | C29: 3700000 | D29: 3700000 | E29: 700000 | F29: 3700000 | G29: 1350000 | H29: 16650000
A30: CPM | B30: 4.41 | C30: 5.25 | D30: 3.22 | E30: 4.41 | F30: 3.85 | G30: 5.6 | H30: 4.3
A31: Cost | B31: 15435 | C31: 19425 | D31: 11914 | E31: 3087 | F31: 14245 | G31: 7560 | H31: 71666
A32: Mobile Ads
A33: Impressions | B33: 3000000 | C33: - | D33: 3000000 | E33: 3000000 | F33: 3000000 | G33: 3000000 | H33: 15000000 | I33: *look for reason of not having mobile ads in korea, if not found use same price
A34: CPM | B34: 0.4 | C34: - | D34: 0.4 | E34: 0.4 | F34: 0.4 | G34: 0.4 | H34: 0.4
A35: Cost | B35: 1200 | C35: - | D35: 1200 | E35: 1200 | F35: 1200 | G35: 1200 | H35: 6000
A36: Total Ads
A37: Impressions | B37: 12500000 | C37: 9700000 | D37: 12700000 | E37: 4700000 | F37: 12700000 | G37: 6350000 | H37: 58650000 | I37: Including agency fee
A38: Cost | B38: 19815 | C38: 24705 | D38: 16714 | E38: 4857 | F38: 18805 | G38: 10180 | H38: 95076 | I38: =H38*1.09 -> 103632.84
A40: EXHIBIT 5: INTEL’S ESTIMATED CLICK-THROUGH RATES AND SOCIAL IMPRESSIONS MULTIPLIERS
A42: Market | B42: Indonesia | C42: Korea | D42: Malaysia | E42: Pakistan | F42: Philippines | G42: Singapore
A43: Marketplace CTR | B43: 0.0009 | C43: 0.0008 | D43: 0.0011 | E43: 0.0012 | F43: 0.0011 | G43: 0.0012
A44: Premium CTR | B44: 0.0043 | C44: 0.0023 | D44: 0.0032 | E44: 0.0059 | F44: 0.0048 | G44: 0.0034 | L44: Then the original plan | M44: 1.25 | N44: Applies to total
A45: Social Impression Multiplier | B45: 12.9 | C45: 41.1 | D45: 21.4 | E45: 26.5 | F45: 32.4 | G45: 20.6 | M45: 0.75 | N45: Applies per type of adv
A46: Social CTR | B46: 0.0196 | C46: 0.0239 | D46: 0.0182 | E46: 0.0264 | F46: 0.0181 | G46: 0.0183
...

Sheet Model 2
A2: Problem | B2: Exceeding budget, optimization of resources
A3: Objective | B3: Decided which marketing plan is better. 1) Agency plan 2) Peter Dingle plans 3) New Plan (other)
A5: EXHIBIT 1: DEMOGRAPHIC AND TECHNOLOGY PENETRATION DATA
A6: Intel AP Markets | B6: Indonesia | C6: Korea | D6: Malaysia | E6: Pakistan | F6: Philippines | G6: Singapore
A7: Population (Ms) 1 | B7: 251.2 | C7: 49 | D7: 29.6 | E7: 193.2 | F7: 105.7 | G7: 5.5
A8: # Internet Users (Ms) 1 | B8: 20 | C8: 39.4 | D8: 15.4 | E8: 20.4 | F8: 8.3 | G8: 3.2
A9: Mobile Phones (Ms) 1 | B9: 248.8 | C9: 52.5 | D9: 36.7 | E9: 111 | F9: 94.2 | G9: 7.8
A10: # Facebook Users (Ms) 2 | B10: 51.1 | C10: 10 | D10: 13.6 | E10: 8 | F10: 29.9 | G10: 2.9
A11: Sources: 1 CIA World Factbook, accessed July 25, 2013; | E11: 2 www.internetworldstats.com/, accessed July 25, 2013.
A13: EXHIBIT 2: INTEL ASIA-PACIFIC FACEBOOK COMMUNITIES (AUGUST 2012)
A14: Intel Market | B14: Indonesia | C14: Korea | D14: Malaysia | E14: Pakistan | F14: Philippines | G14: Singapore
A15: Fans | B15: 778144 | C15: 137801 | D15: 128410 | E15: 316425 | F15: 203907 | G15: 15595
A16: Growth | B16: 8009 | C16: 9361 | D16: 2932 | E16: 18994 | F16: 2204 | G16: 1496
A17: Top Demographic | B17: M 18-24 | C17: F 18-24 | D17: M 18-24 | E17: M 18-24 | F17: M 18-24 | G17: M 18-24
A18: Growth % | B18: =B16/B15 -> 0.010292439 | C18: =C16/C15 -> 0.067931292 | D18: =D16/D15 -> 0.022833113 | E18: =E16/E15 -> 0.060026863 | F18: =F16/F15 -> 0.010808849 | G18: =G16/G15 -> 0.095928182
A19: Source: Intel Asia-Pacific Marketing
A21: Page 9 | H21: 9B13E023
A22: EXHIBIT 4: PRELIMINARY MEDIA PLAN PROPOSED BY IMPACT MARKETING LTD
B23: Indonesia | C23: Korea | D23: Malaysia | E23: Pakistan | F23: Philippines | G23: Singapore | H23: Total
A24: Marketplace
A25: Impressions | B25: 6000000 | C25: 6000000 | D25: 6000000 | E25: 1000000 | F25: 6000000 | G25: 2000000 | H25: 27000000
A26: CPM | B26: 0.53 | C26: 0.88 | D26: 0.6 | E26: 0.57 | F26: 0.56 | G26: 0.71 | H26: 0.64
A27: Cost | B27: 3180 | C27: 5280 | D27: 3600 | E27: 570 | F27: 3360 | G27: 1420 | H27: 17410
A28: Premium
A29: Impressions | B29: 3500000 | C29: 3700000 | D29: 3700000 | E29: 700000 | F29: 3700000 | G29: 1350000 | H29: 16650000
A30: CPM | B30: 4.41 | C30: 5.25 | D30: 3.22 | E30: 4.41 | F30: 3.85 | G30: 5.6 | H30: 4.3
A31: Cost | B31: 15435 | C31: 19425 | D31: 11914 | E31: 3087 | F31: 14245 | G31: 7560 | H31: 71666
A32: Mobile Ads
A33: Impressions | B33: 3000000 | C33: - | D33: 3000000 | E33: 3000000 | F33: 3000000 | G33: 3000000 | H33: 15000000 | I33: *look for reason of not having mobile ads in korea, if not found use same price
A34: CPM | B34: 0.4 | C34: - | D34: 0.4 | E34: 0.4 | F34: 0.4 | G34: 0.4 | H34: 0.4
A35: Cost | B35: 1200 | C35: - | D35: 1200 | E35: 1200 | F35: 1200 | G35: 1200 | H35: 6000
A36: Total Ads
A37: Impressions | B37: 12500000 | C37: 9700000 | D37: 12700000 | E37: 4700000 | F37: 12700000 | G37: 6350000 | H37: 58650000 | I37: Including agency fee
A38: Cost | B38: 19815 | C38: 24705 | D38: 16714 | E38: 4857 | F38: 18805 | G38: 10180 | H38: 95076 | I38: =H38*1.09 -> 103632.84
A40: EXHIBIT 5: INTEL’S ESTIMATED CLICK-THROUGH RATES AND SOCIAL IMPRESSIONS MULTIPLIERS
A42: Market | B42: Indonesia | C42: Korea | D42: Malaysia | E42: Pakistan | F42: Philippines | G42: Singapore
A43: Marketplace CTR | B43: 0.0009 | C43: 0.0008 | D43: 0.0011 | E43: 0.0012 | F43: 0.0011 | G43: 0.0012
A44: Premium CTR | B44: 0.0043 | C44: 0.0023 | D44: 0.0032 | E44: 0.0059 | F44: 0.0048 | G44: 0.0034 | L44: Then the original plan | M44: 1.25 | N44: Applies to total
A45: Social Impression Multiplier | B45: 12.9 | C45: 41.1 | D45: 21.4 | E45: 26.5 | F45: 32.4 | G45: 20.6 | M45: 0.75 | N45: Applies per type of adv
A46: Social CTR | B46: 0.0196 | C46: 0.0239 | D46: 0.0182 | E46: 0.0264 | F46: 0.0181 | G46: 0.0183
...

Sheet Model 2 Modify
A2: Problem | B2: Exceeding budget, optimization of resources
A3: Objective | B3: Decided which marketing plan is better. 1) Agency plan 2) Peter Dingle plans 3) New Plan (other)
A5: EXHIBIT 1: DEMOGRAPHIC AND TECHNOLOGY PENETRATION DATA
A6: Intel AP Markets | B6: Indonesia | C6: Korea | D6: Malaysia | E6: Pakistan | F6: Philippines | G6: Singapore
A7: Population (Ms) 1 | B7: 251.2 | C7: 49 | D7: 29.6 | E7: 193.2 | F7: 105.7 | G7: 5.5
A8: # Internet Users (Ms) 1 | B8: 20 | C8: 39.4 | D8: 15.4 | E8: 20.4 | F8: 8.3 | G8: 3.2
A9: Mobile Phones (Ms) 1 | B9: 248.8 | C9: 52.5 | D9: 36.7 | E9: 111 | F9: 94.2 | G9: 7.8
A10: # Facebook Users (Ms) 2 | B10: 51.1 | C10: 10 | D10: 13.6 | E10: 8 | F10: 29.9 | G10: 2.9
A11: Sources: 1 CIA World Factbook, accessed July 25, 2013; | E11: 2 www.internetworldstats.com/, accessed July 25, 2013.
A13: EXHIBIT 2: INTEL ASIA-PACIFIC FACEBOOK COMMUNITIES (AUGUST 2012)
A14: Intel Market | B14: Indonesia | C14: Korea | D14: Malaysia | E14: Pakistan | F14: Philippines | G14: Singapore
A15: Fans | B15: 778144 | C15: 137801 | D15: 128410 | E15: 316425 | F15: 203907 | G15: 15595
A16: Growth | B16: 8009 | C16: 9361 | D16: 2932 | E16: 18994 | F16: 2204 | G16: 1496
A17: Top Demographic | B17: M 18-24 | C17: F 18-24 | D17: M 18-24 | E17: M 18-24 | F17: M 18-24 | G17: M 18-24
A18: Growth % | B18: =B16/B15 -> 0.010292439 | C18: =C16/C15 -> 0.067931292 | D18: =D16/D15 -> 0.022833113 | E18: =E16/E15 -> 0.060026863 | F18: =F16/F15 -> 0.010808849 | G18: =G16/G15 -> 0.095928182
A19: Source: Intel Asia-Pacific Marketing
A21: Page 9 | H21: 9B13E023
A22: EXHIBIT 4: PRELIMINARY MEDIA PLAN PROPOSED BY IMPACT MARKETING LTD
B23: Indonesia | C23: Korea | D23: Malaysia | E23: Pakistan | F23: Philippines | G23: Singapore | H23: Total
A24: Marketplace
A25: Impressions | B25: 6000000 | C25: 6000000 | D25: 6000000 | E25: 1000000 | F25: 6000000 | G25: 2000000 | H25: 27000000
A26: CPM | B26: 0.53 | C26: 0.88 | D26: 0.6 | E26: 0.57 | F26: 0.56 | G26: 0.71 | H26: 0.64
A27: Cost | B27: 3180 | C27: 5280 | D27: 3600 | E27: 570 | F27: 3360 | G27: 1420 | H27: 17410
A28: Premium
A29: Impressions | B29: 3500000 | C29: 3700000 | D29: 3700000 | E29: 700000 | F29: 3700000 | G29: 1350000 | H29: 16650000
A30: CPM | B30: 4.41 | C30: 5.25 | D30: 3.22 | E30: 4.41 | F30: 3.85 | G30: 5.6 | H30: 4.3
A31: Cost | B31: 15435 | C31: 19425 | D31: 11914 | E31: 3087 | F31: 14245 | G31: 7560 | H31: 71666
A32: Mobile Ads
A33: Impressions | B33: 3000000 | C33: - | D33: 3000000 | E33: 3000000 | F33: 3000000 | G33: 3000000 | H33: 15000000 | I33: *look for reason of not having mobile ads in korea, if not found use same price
A34: CPM | B34: 0.4 | C34: - | D34: 0.4 | E34: 0.4 | F34: 0.4 | G34: 0.4 | H34: 0.4
A35: Cost | B35: 1200 | C35: - | D35: 1200 | E35: 1200 | F35: 1200 | G35: 1200 | H35: 6000
A36: Total Ads
A37: Impressions | B37: 12500000 | C37: 9700000 | D37: 12700000 | E37: 4700000 | F37: 12700000 | G37: 6350000 | H37: 58650000 | I37: Including agency fee
A38: Cost | B38: 19815 | C38: 24705 | D38: 16714 | E38: 4857 | F38: 18805 | G38: 10180 | H38: 95076 | I38: =H38*1.09 -> 103632.84
A40: EXHIBIT 5: INTEL’S ESTIMATED CLICK-THROUGH RATES AND SOCIAL IMPRESSIONS MULTIPLIERS
A42: Market | B42: Indonesia | C42: Korea | D42: Malaysia | E42: Pakistan | F42: Philippines | G42: Singapore
A43: Marketplace CTR | B43: 0.0009 | C43: 0.0008 | D43: 0.0011 | E43: 0.0012 | F43: 0.0011 | G43: 0.0012
A44: Premium CTR | B44: 0.0043 | C44: 0.0023 | D44: 0.0032 | E44: 0.0059 | F44: 0.0048 | G44: 0.0034 | L44: Then the original plan | M44: 1.25 | N44: Applies to total
A45: Social Impression Multiplier | B45: 12.9 | C45: 41.1 | D45: 21.4 | E45: 26.5 | F45: 32.4 | G45: 20.6 | M45: 0.75 | N45: Applies per type of adv
A46: Social CTR | B46: 0.0196 | C46: 0.0239 | D46: 0.0182 | E46: 0.0264 | F46: 0.0181 | G46: 0.0183
...

Sheet Answer Report 1
A1: Microsoft Excel 16.0 Answer Report
A2: Worksheet: [Case_Intel_Asia_Campaign_FINAL.xlsx]Model 1
A3: Report Created: 2/11/2020 11:55:18 AM
A4: Result: Solver found an integer solution within tolerance. All Constraints are satisfied.
A5: Solver Engine
B6: Engine: Simplex LP
B7: Solution Time: 0.219 Seconds.
B8: Iterations: 2 Subproblems: 30
A9: Solver Options
B10: Max Time Unlimited, Iterations Unlimited, Precision 0.000001
B11: Max Subproblems Unlimited, Max Integer Sols Unlimited, Integer Tolerance 1%, Assume NonNegative
A14: Objective Cell (Max)
B15: Cell | C15: Name | D15: Original Value | E15: Final Value
B16: $B$50 | C16: Max Clicks Indonesia | D16: 134121.21 | E16: 134121.21
A19: Variable Cells
B20: Cell | C20: Name | D20: Original Value | E20: Final Value | F20: Integer
B21: $D$61 | C21: Marketplace Model | D21: 4500000 | E21: 4500000 | F21: Integer
B22: $D$62 | C22: Premium Model | D22: 2625000 | E22: 2625000 | F22: Integer
B23: $D$63 | C23: Mobile Ads Model | D23: 2250000 | E23: 2250000 | F23: Integer
B24: $D$65 | C24: Marketplace Model | D24: 4500000 | E24: 4500000 | F24: Integer
B25: $D$66 | C25: Premium Model | D25: 2775000 | E25: 2775000 | F25: Integer
B26: $D$67 | C26: Mobile Ads Model | D26: 4850000 | E26: 4850000 | F26: Integer
B27: $D$69 | C27: Marketplace Model | D27: 4500000 | E27: 4500000 | F27: Integer
B28: $D$70 | C28: Premium Model | D28: 2775000 | E28: 2775000 | F28: Integer
B29: $D$71 | C29: Mobile Ads Model | D29: 2250000 | E29: 2250000 | F29: Integer
B30: $D$74 | C30: Premium Model | D30: 2875000 | E30: 2875000 | F30: Integer
B31: $D$75 | C31: Mobile Ads Model | D31: 2250000 | E31: 2250000 | F31: Integer
B32: $D$73 | C32: Marketplace Model | D32: 750000 | E32: 750000 | F32: Integer
... B38: $D$83 | C38: Mobile Ads Model | D38: 2250000 | E38: 2250000 | F38: Integer
A41: Constraints
B42: Cell | C42: Name | D42: Cell Value | E42: Formula | F42: Status | G42: Slack
B43: $D$60 | C43: Indonesia Model | D43: 9375000 | E43: $D$60<=$W$60 | F43: Not Binding | G43: 6250000
B44: $D$64 | C44: Korea Model | D44: 12125000 | E44: $D$64<=$W$64 | F44: Binding | G44: 0
B45: $D$68 | C45: Malaysia Model | D45: 9525000 | E45: $D$68<=$W$68 | F45: Not Binding | G45: 6350000
B46: $D$72 | C46: Pakistan Model | D46: 5875000 | E46: $D$72<=$W$72 | F46: Binding | G46: 0
B47: $D$76 | C47: Philippines Model | D47: 10445913 | E47: $D$76<=$W$76 | F47: Not Binding | G47: 5429087
B48: $D$80 | C48: Singapore Model | D48: 4762500 | E48: $D$80<=$W$80 | F48: Not Binding | G48: 3175000
B49: $L$85 | C49: TOTAL Model | D49: 95000 | E49: $L$85<=$Z$60 | F49: Not Binding | G49: 2.9999937e-06
B50: $D$61 | C50: Marketplace Model | D50: 4500000 | E50: $D$61>=$W$61 | F50: Binding | G50: 0
B51: $D$62 | C51: Premium Model | D51: 2625000 | E51: $D$62>=$W$62 | F51: Binding | G51: 0
...

Sheet Model 1
A2: Problem | B2: Exceeding budget, optimization of resources
A3: Objective | B3: Decided which marketing plan is better. 1) Agency plan 2) Peter Dingle plans 3) New Plan (other)
A5: EXHIBIT 1: DEMOGRAPHIC AND TECHNOLOGY PENETRATION DATA
A6: Intel AP Markets | B6: Indonesia | C6: Korea | D6: Malaysia | E6: Pakistan | F6: Philippines | G6: Singapore
A7: Population (Ms) 1 | B7: 251.2 | C7: 49 | D7: 29.6 | E7: 193.2 | F7: 105.7 | G7: 5.5
A8: # Internet Users (Ms) 1 | B8: 20 | C8: 39.4 | D8: 15.4 | E8: 20.4 | F8: 8.3 | G8: 3.2
A9: Mobile Phones (Ms) 1 | B9: 248.8 | C9: 52.5 | D9: 36.7 | E9: 111 | F9: 94.2 | G9: 7.8
A10: # Facebook Users (Ms) 2 | B10: 51.1 | C10: 10 | D10: 13.6 | E10: 8 | F10: 29.9 | G10: 2.9
A11: Sources: 1 CIA World Factbook, accessed July 25, 2013; | E11: 2 www.internetworldstats.com/, accessed July 25, 2013.
A13: EXHIBIT 2: INTEL ASIA-PACIFIC FACEBOOK COMMUNITIES (AUGUST 2012)
A14: Intel Market | B14: Indonesia | C14: Korea | D14: Malaysia | E14: Pakistan | F14: Philippines | G14: Singapore
A15: Fans | B15: 778144 | C15: 137801 | D15: 128410 | E15: 316425 | F15: 203907 | G15: 15595
A16: Growth | B16: 8009 | C16: 9361 | D16: 2932 | E16: 18994 | F16: 2204 | G16: 1496
A17: Top Demographic | B17: M 18-24 | C17: F 18-24 | D17: M 18-24 | E17: M 18-24 | F17: M 18-24 | G17: M 18-24
A18: Growth % | B18: =B16/B15 -> 0.010292439 | C18: =C16/C15 -> 0.067931292 | D18: =D16/D15 -> 0.022833113 | E18: =E16/E15 -> 0.060026863 | F18: =F16/F15 -> 0.010808849 | G18: =G16/G15 -> 0.095928182
A19: Source: Intel Asia-Pacific Marketing
A21: Page 9 | H21: 9B13E023
A22: EXHIBIT 4: PRELIMINARY MEDIA PLAN PROPOSED BY IMPACT MARKETING LTD
B23: Indonesia | C23: Korea | D23: Malaysia | E23: Pakistan | F23: Philippines | G23: Singapore | H23: Total
A24: Marketplace
A25: Impressions | B25: 6000000 | C25: 6000000 | D25: 6000000 | E25: 1000000 | F25: 6000000 | G25: 2000000 | H25: 27000000
A26: CPM | B26: 0.53 | C26: 0.88 | D26: 0.6 | E26: 0.57 | F26: 0.56 | G26: 0.71 | H26: 0.64
A27: Cost | B27: 3180 | C27: 5280 | D27: 3600 | E27: 570 | F27: 3360 | G27: 1420 | H27: 17410
A28: Premium
A29: Impressions | B29: 3500000 | C29: 3700000 | D29: 3700000 | E29: 700000 | F29: 3700000 | G29: 1350000 | H29: 16650000
A30: CPM | B30: 4.41 | C30: 5.25 | D30: 3.22 | E30: 4.41 | F30: 3.85 | G30: 5.6 | H30: 4.3
A31: Cost | B31: 15435 | C31: 19425 | D31: 11914 | E31: 3087 | F31: 14245 | G31: 7560 | H31: 71666
A32: Mobile Ads
A33: Impressions | B33: 3000000 | C33: - | D33: 3000000 | E33: 3000000 | F33: 3000000 | G33: 3000000 | H33: 15000000 | I33: *look for reason of not having mobile ads in korea, if not found use same price
A34: CPM | B34: 0.4 | C34: - | D34: 0.4 | E34: 0.4 | F34: 0.4 | G34: 0.4 | H34: 0.4
A35: Cost | B35: 1200 | C35: - | D35: 1200 | E35: 1200 | F35: 1200 | G35: 1200 | H35: 6000
A36: Total Ads
A37: Impressions | B37: 12500000 | C37: 9700000 | D37: 12700000 | E37: 4700000 | F37: 12700000 | G37: 6350000 | H37: 58650000 | I37: Including agency fee
A38: Cost | B38: 19815 | C38: 24705 | D38: 16714 | E38: 4857 | F38: 18805 | G38: 10180 | H38: 95076 | I38: =H38*1.09 -> 103632.84
A40: EXHIBIT 5: INTEL’S ESTIMATED CLICK-THROUGH RATES AND SOCIAL IMPRESSIONS MULTIPLIERS
A42: Market | B42: Indonesia | C42: Korea | D42: Malaysia | E42: Pakistan | F42: Philippines | G42: Singapore
A43: Marketplace CTR | B43: 0.0009 | C43: 0.0008 | D43: 0.0011 | E43: 0.0012 | F43: 0.0011 | G43: 0.0012
A44: Premium CTR | B44: 0.0043 | C44: 0.0023 | D44: 0.0032 | E44: 0.0059 | F44: 0.0048 | G44: 0.0034 | L44: Then the original plan | M44: 1.25 | N44: Applies to total
A45: Social Impression Multiplier | B45: 12.9 | C45: 41.1 | D45: 21.4 | E45: 26.5 | F45: 32.4 | G45: 20.6 | M45: 0.75 | N45: Applies per type of adv
A46: Social CTR | B46: 0.0196 | C46: 0.0239 | D46: 0.0182 | E46: 0.0264 | F46: 0.0181 | G46: 0.0183
...

Sheet RAW DATA
A2: Problem | B2: Exceeding budget, optimization of resources
A3: Objective | B3: Decided which marketing plan is better. 1) Agency plan 2) Peter Dingle plans 3) New Plan (other)
A5: EXHIBIT 1: DEMOGRAPHIC AND TECHNOLOGY PENETRATION DATA
A6: Intel AP Markets | B6: Indonesia | C6: Korea | D6: Malaysia | E6: Pakistan | F6: Philippines | G6: Singapore
A7: Population (Ms) 1 | B7: 251.2 | C7: 49 | D7: 29.6 | E7: 193.2 | F7: 105.7 | G7: 5.5
A8: # Internet Users (Ms) 1 | B8: 20 | C8: 39.4 | D8: 15.4 | E8: 20.4 | F8: 8.3 | G8: 3.2
A9: Mobile Phones (Ms) 1 | B9: 248.8 | C9: 52.5 | D9: 36.7 | E9: 111 | F9: 94.2 | G9: 7.8
A10: # Facebook Users (Ms) 2 | B10: 51.1 | C10: 10 | D10: 13.6 | E10: 8 | F10: 29.9 | G10: 2.9
A11: Sources: 1 CIA World Factbook, accessed July 25, 2013; | E11: 2 www.internetworldstats.com/, accessed July 25, 2013.
A13: EXHIBIT 2: INTEL ASIA-PACIFIC FACEBOOK COMMUNITIES (AUGUST 2012)
A14: Intel Market | B14: Indonesia | C14: Korea | D14: Malaysia | E14: Pakistan | F14: Philippines | G14: Singapore
A15: Fans | B15: 778144 | C15: 137801 | D15: 128410 | E15: 316425 | F15: 203907 | G15: 15595
A16: Growth | B16: 8009 | C16: 9361 | D16: 2932 | E16: 18994 | F16: 2204 | G16: 1496
A17: Top Demographic | B17: M 18-24 | C17: F 18-24 | D17: M 18-24 | E17: M 18-24 | F17: M 18-24 | G17: M 18-24
A18: Growth % | B18: =B16/B15 -> 0.010292439 | C18: =C16/C15 -> 0.067931292 | D18: =D16/D15 -> 0.022833113 | E18: =E16/E15 -> 0.060026863 | F18: =F16/F15 -> 0.010808849 | G18: =G16/G15 -> 0.095928182
A19: Source: Intel Asia-Pacific Marketing
A21: EXHIBIT 4: PRELIMINARY MEDIA PLAN PROPOSED BY IMPACT MARKETING LTD
B22: Indonesia | C22: Korea | D22: Malaysia | E22: Pakistan | F22: Philippines | G22: Singapore | H22: Total
A23: Marketplace
A24: Impressions | B24: 6000000 | C24: 6000000 | D24: 6000000 | E24: 1000000 | F24: 6000000 | G24: 2000000 | H24: 27000000
A25: CPM | B25: 0.53 | C25: 0.88 | D25: 0.6 | E25: 0.57 | F25: 0.56 | G25: 0.71 | H25: 0.64
A26: Cost | B26: 3180 | C26: 5280 | D26: 3600 | E26: 570 | F26: 3360 | G26: 1420 | H26: 17410
A27: Premium
A28: Impressions | B28: 3500000 | C28: 3700000 | D28: 3700000 | E28: 700000 | F28: 3700000 | G28: 1350000 | H28: 16650000
A29: CPM | B29: 4.41 | C29: 5.25 | D29: 3.22 | E29: 4.41 | F29: 3.85 | G29: 5.6 | H29: 4.3
A30: Cost | B30: 15435 | C30: 19425 | D30: 11914 | E30: 3087 | F30: 14245 | G30: 7560 | H30: 71666
A31: Mobile Ads
A32: Impressions | B32: 3000000 | C32: - | D32: 3000000 | E32: 3000000 | F32: 3000000 | G32: 3000000 | H32: 15000000 | I32: *look for reason of not having mobile ads in korea, if not found use same price
A33: CPM | B33: 0.4 | C33: - | D33: 0.4 | E33: 0.4 | F33: 0.4 | G33: 0.4 | H33: 0.4
A34: Cost | B34: 1200 | C34: - | D34: 1200 | E34: 1200 | F34: 1200 | G34: 1200 | H34: 6000
A35: Total Ads
A36: Impressions | B36: 12500000 | C36: 9700000 | D36: 12700000 | E36: 4700000 | F36: 12700000 | G36: 6350000 | H36: 58650000 | I36: Including agency fee
A37: Cost | B37: 19815 | C37: 24705 | D37: 16714 | E37: 4857 | F37: 18805 | G37: 10180 | H37: 95076 | I37: =H37*1.09 -> 103632.84
A39: EXHIBIT 5: INTEL’S ESTIMATED CLICK-THROUGH RATES AND SOCIAL IMPRESSIONS MULTIPLIERS
A41: Market | B41: Indonesia | C41: Korea | D41: Malaysia | E41: Pakistan | F41: Philippines | G41: Singapore
A42: Marketplace CTR | B42: 0.0009 | C42: 0.0008 | D42: 0.0011 | E42: 0.0012 | F42: 0.0011 | G42: 0.0012
A43: Premium CTR | B43: 0.0043 | C43: 0.0023 | D43: 0.0032 | E43: 0.0059 | F43: 0.0048 | G43: 0.0034 | L43: Then the original plan | M43: 1.25 | N43: Applies to total
A44: Social Impression Multiplier | B44: 12.9 | C44: 41.1 | D44: 21.4 | E44: 26.5 | F44: 32.4 | G44: 20.6 | M44: 0.75 | N44: Applies per type of adv
A45: Social CTR | B45: 0.0196 | C45: 0.0239 | D45: 0.0182 | E45: 0.0264 | F45: 0.0181 | G45: 0.0183
A46: CTR Mobile Ad | B46: 0.0005 | C46: 0.0005 | D46: 0.0005 | E46: 0.0005 | F46: 0.0005 | G46: 0.0005
...

Sheet FB Users
F2: Impressions | I2: Impressions/FB Users
C3: # FB Users (MM) | D3: Social Impression Multiplier | E3: Social CTR | F3: Agency (MM) | G3: Original (MM) | H3: Alt. (MM) | I3: Agency | J3: Original | K3: Alternative
B4: Indonesia | C4: ='Model 2.'!S61 -> 51.1 | D4: ='Model 2.'!AC61 -> 12.9 | E4: ='Model 2.'!AD61 -> 0.0196 | F4: =('Model 1'!C60)/1000000 -> 12.5 | G4: =('Model 1'!D60)/1000000 -> 9.375 | H4: =('Model 2.'!D61)/1000000 -> 15.33 | I4: =F4/$C4 -> 0.2446184 | J4: =G4/$C4 -> 0.1834638 | K4: =H4/$C4 -> 0.3
B5: Korea | C5: ='Model 2.'!S65 -> 10 | D5: ='Model 2.'!AC65 -> 41.1 | E5: ='Model 2.'!AD65 -> 0.0239 | F5: =('Model 1'!C64)/1000000 -> 9.7 | G5: =('Model 1'!D64)/1000000 -> 12.125 | H5: =('Model 2.'!D65)/1000000 -> 10 | I5: =F5/$C5 -> 0.97 | J5: =G5/$C5 -> 1.2125 | K5: =H5/$C5 -> 1 | L5: Mobile Ads
B6: Malaysia | C6: ='Model 2.'!S69 -> 13.6 | D6: ='Model 2.'!AC69 -> 21.4 | E6: ='Model 2.'!AD69 -> 0.0182 | F6: =('Model 1'!C68)/1000000 -> 12.7 | G6: =('Model 1'!D68)/1000000 -> 9.525 | H6: =('Model 2.'!D69)/1000000 -> 6.35 | I6: =F6/$C6 -> 0.93382353 | J6: =G6/$C6 -> 0.70036765 | K6: =H6/$C6 -> 0.46691176
B7: Pakistan | C7: ='Model 2.'!S73 -> 8 | D7: ='Model 2.'!AC73 -> 26.5 | E7: ='Model 2.'!AD73 -> 0.0264 | F7: =('Model 1'!C72)/1000000 -> 4.7 | G7: =('Model 1'!D72)/1000000 -> 5.875 | H7: =('Model 2.'!D73)/1000000 -> 7.05 | I7: =F7/$C7 -> 0.5875 | J7: =G7/$C7 -> 0.734375 | K7: =H7/$C7 -> 0.88125
B8: Philippines | C8: ='Model 2.'!S77 -> 29.9 | D8: ='Model 2.'!AC77 -> 32.4 | E8: ='Model 2.'!AD77 -> 0.0181 | F8: =('Model 1'!C76)/1000000 -> 12.7 | G8: =('Model 1'!D76)/1000000 -> 10.445913 | H8: =('Model 2.'!D77)/1000000 -> 9.6567957 | I8: =F8/$C8 -> 0.42474916 | J8: =G8/$C8 -> 0.34936164 | K8: =H8/$C8 -> 0.32296975
B9: Singapore | C9: ='Model 2.'!S81 -> 2.9 | D9: ='Model 2.'!AC81 -> 20.6 | E9: ='Model 2.'!AD81 -> 0.0183 | F9: =('Model 1'!C80)/1000000 -> 6.35 | G9: =('Model 1'!D80)/1000000 -> 4.7625 | H9: =('Model 2.'!D81)/1000000 -> 2.7305 | I9: =F9/$C9 -> 2.1896552 | J9: =G9/$C9 -> 1.6422414 | K9: =H9/$C9 -> 0.94155172 | L9: Mobile Ads
B10: Total | C10: =SUM(C4:C9) -> 115.5 | F10: =SUM(F4:F9) -> 58.65 | G10: =SUM(G4:G9) -> 52.108413 | H10: =SUM(H4:H9) -> 51.117296 | I10: =F10/$C10 -> 0.50779221 | J10: =G10/$C10 -> 0.45115509 | K10: =H10/$C10 -> 0.44257399
